<?xml version="1.0"?>
<robot  
  xmlns:xacro="http://ros.org/wiki/xacro">
  <xacro:property name="M_PI" value="3.1415926535897931" />

  <xacro:macro name="pioneer_wheel" params="name parent xyz rpy radius models_dir:=^ **contact_data">   

    <!-- Wheel -->
    <joint name="${name}_wheel_joint" type="continuous">
		<origin xyz="${xyz}" rpy="${rpy}"/>
		<axis xyz="0 1 0"/>
		<parent link="${parent}"/>
		<child link="${name}_wheel"/>
    </joint>
    <link name="${name}_wheel">
		<inertial>
			<mass value="0.5"/>
			<origin xyz="0 0 0"/>
			<inertia ixx="0.012411765597" ixy="0" ixz="0" iyy="0.015218160428" iyz="0" izz="0.011763977943"/>
		</inertial>
		<visual>
			<origin xyz="0 0 0" rpy="0 0 0"/>
			<geometry> <mesh filename="file://${models_dir}/pioneer3dx/body/meshes/wheel.dae"/> </geometry>
			<material name="WheelBlack"> <color rgba="0.117 0.117 0.117 1"/> </material>
		</visual>
		<collision>
			<origin xyz="0 0 0" rpy="${pi/2} 0 0"/>
			<geometry> <cylinder radius="${radius}" length="0.001"/> <!--<mesh filename="${meshes}/${name}_wheel.stl"/>--> </geometry>
		</collision>
    </link>
		<gazebo reference="${name}_wheel">
		<material value="Gazebo/Black"/>
	<xacro:insert_block name="contact_data"/>
    </gazebo>

    <!-- Hubcap -->
    <joint name="${name}_hub_joint" type="fixed">
		<origin xyz="0 0 0" rpy="0 0 0"/>
		<axis xyz="0 1 0"/>
		<parent link="${name}_wheel"/>
		<child link="${name}_hub"/>
    </joint>
    <link name="${name}_hub">
		<inertial>
			<mass value="0.01"/>
			<origin xyz="0 0 0"/>
			<inertia ixx="0.012411765597" ixy="0" ixz="0" iyy="0.015218160428" iyz="0" izz="0.011763977943"/>
		</inertial>
		<visual>
			<origin xyz="0 0 0" rpy="0 0 0"/>
			<geometry> <mesh filename="file://${models_dir}/pioneer3dx/body/meshes/hubcap.dae"/> </geometry>
			<material name="HubcapYellow"> <color rgba="1.0 0.811 0.151 1.0"/> </material>
		</visual>
		<collision>
			<origin xyz="0 0 0" rpy="0 0 0"/>
			<geometry> <box size="0.001 0.001 0.001"/> </geometry>
		</collision>
    </link>
		<gazebo reference="${name}_hub">
		<material value="Gazebo/Yellow"/>
    </gazebo>
  
  </xacro:macro>

</robot>
