<?xml version="1.0"?>
<robot xmlns:xacro="http://ros.org/wiki/xacro">

<xacro:include filename="$(find tuw_gazebo_models)/models/inertia_tensors.xacro"/>

<xacro:macro name="I2wsWheel" params="name parent fb lr wheel_radius wheel_length mesh_collis:=^|simplified mesh_visual:=^|detailed model_dir:=^"> 
    
    <xacro:property name="ParrentLink2ThisLink"> <!--parrent link to this joint tf-->
	<origin xyz="0 0 0"  rpy="${pi} ${pi/2} 0"/> 
    </xacro:property>

    <xacro:property name="ThisLink2Inert"> <!--this link 2 inertial center tf, mass data-->
	<cylinder_inertial radius="${wheel_radius}" length="${wheel_length}" mass="0.197"/>
    </xacro:property>

    <xacro:property name="ThisLink2STL"> <!--this link 2 mesh center tf, file-->
	<origin xyz="0 0 0" rpy="0 ${pi/2} 0"/> 
	<geometry> <mesh filename="file://${model_dir}/meshes/wheel_red.stl"/> </geometry>
	<material name="white"/> 
    </xacro:property>

    <xacro:property name="ThisLink2XML"> <!--this link 2 simple mesh center tf, file-->
	<origin xyz="0 0 0" rpy="0 0 0"/> 
	<geometry> <cylinder radius="${wheel_radius}" length="${wheel_length}" /> </geometry>
	<material name="white"/> 
    </xacro:property>
	
    <!-- choosing the appropriate collision and visual mesh -->
    <xacro:property name="ThisVisual"> <xacro:insert_block name="ThisLink2XML"/> </xacro:property><!--minimalist mesh-->
    <xacro:property name="ThisCollis"> <xacro:insert_block name="ThisLink2XML"/> </xacro:property><!--minimalist mesh-->
    <xacro:if value="${mesh_visual ==   'detailed'}"> <xacro:property name="ThisVisual">  <xacro:insert_block name="ThisLink2STL"/> </xacro:property> </xacro:if><!--detailed stl mesh-->
    <xacro:if value="${mesh_collis ==   'detailed'}"> <xacro:property name="ThisCollis">  <xacro:insert_block name="ThisLink2STL"/> </xacro:property> </xacro:if><!--detailed stl mesh-->
    
    
    <!-- joint and link definition -->
    <joint name="${parent}${fb}${lr}2${name}${fb}${lr}_joint" type="continuous">
	<parent link="${parent}${fb}${lr}_link" />
	<child  link="${name}${fb}${lr}_link" />
	<axis   xyz="0 0 1"/>
	<xacro:insert_block name="ParrentLink2ThisLink" />
    </joint>

    <link name="${name}${fb}${lr}_link">    
	<xacro:insert_block name="ThisLink2Inert"/>
	<visual>    <xacro:insert_block name="ThisVisual"/> </visual>
	<collision> <xacro:insert_block name="ThisCollis"/> </collision>
    </link>
    <gazebo reference="${name}${fb}${lr}_link">
	<material>Gazebo/White</material>
	<selfCollide>false</selfCollide>
	<mu1 value="5.9"/>
	<mu2 value="5.9"/>
	<!--fdir1>0 0 1</fdir1-->

	<minDepth value="0.002"/>
	<kp value="1000000.0"/>
	<kd value="10.0"/>
    </gazebo>
	
</xacro:macro>

</robot>
